$ python3 -m unittest tests/test_config_system.py
----------------------------------------
2025-03-09 15:04:20,126 - CodeConductor - INFO - Wrote config to: /var/folders/xs/91hrztpj6hvgcqdz_fkxrcdc0000gn/T/tmp1aoghg5m/_AI-Setup/config.json
E2025-03-09 15:04:20,130 - CodeConductor - INFO - Wrote config to: /var/folders/xs/91hrztpj6hvgcqdz_fkxrcdc0000gn/T/tmpj85tyu2z/_AI-Setup/config.json
2025-03-09 15:04:20,130 - CodeConductor - INFO - Found config file at: /var/folders/xs/91hrztpj6hvgcqdz_fkxrcdc0000gn/T/tmpj85tyu2z/_AI-Setup/config.json
.2025-03-09 15:04:20,134 - CodeConductor - INFO - Wrote config to: /var/folders/xs/91hrztpj6hvgcqdz_fkxrcdc0000gn/T/tmpuboxoogc/_AI-Setup/config.json
2025-03-09 15:04:20,134 - CodeConductor - INFO - Found config file at: /Users/ctavolazzi/Code/code_conductor/_AI-Setup/config.json
F2025-03-09 15:04:20,139 - CodeConductor - INFO - Found config file at: /Users/ctavolazzi/Code/code_conductor/_AI-Setup/config.json
F2025-03-09 15:04:20,143 - CodeConductor - INFO - Wrote config to: /var/folders/xs/91hrztpj6hvgcqdz_fkxrcdc0000gn/T/tmpsnv8ebcq/_AI-Setup/config.json
2025-03-09 15:04:20,143 - CodeConductor - INFO - Found config file at: /Users/ctavolazzi/Code/code_conductor/_AI-Setup/config.json
F2025-03-09 15:04:20,147 - CodeConductor - INFO - Wrote config to: /var/folders/xs/91hrztpj6hvgcqdz_fkxrcdc0000gn/T/tmp5f3dskn_/_AI-Setup/config.json
2025-03-09 15:04:20,147 - CodeConductor - INFO - Found config file at: /Users/ctavolazzi/Code/code_conductor/_AI-Setup/config.json
F/Users/ctavolazzi/Code/code_conductor/tests/test_config_system.py:158: RuntimeWarning: coroutine 'setup_ai_in_current_dir' was never awaited
  setup_ai_in_current_dir()
RuntimeWarning: Enable tracemalloc to get the object allocation traceback
F2025-03-09 15:04:20,165 - CodeConductor - INFO - Wrote config to: /var/folders/xs/91hrztpj6hvgcqdz_fkxrcdc0000gn/T/tmp8y_mvl0y/_AI-Setup/config.json
2025-03-09 15:04:20,166 - CodeConductor - INFO - Read existing config from: /var/folders/xs/91hrztpj6hvgcqdz_fkxrcdc0000gn/T/tmp8y_mvl0y/_AI-Setup/config.json
2025-03-09 15:04:20,166 - CodeConductor - INFO - Wrote config to: /var/folders/xs/91hrztpj6hvgcqdz_fkxrcdc0000gn/T/tmp8y_mvl0y/_AI-Setup/config.json
.
======================================================================
ERROR: test_create_config (tests.test_config_system.TestConfigSystem)
Test creating a new config file.
----------------------------------------------------------------------
Traceback (most recent call last):
  File "/Users/ctavolazzi/Code/code_conductor/tests/test_config_system.py", line 53, in test_create_config
    self.assertEqual(config["work_efforts"]["location"], "in_ai_setup")
KeyError: 'work_efforts'

======================================================================
FAIL: test_find_work_efforts_dir_from_subdir (tests.test_config_system.TestConfigSystem)
Test finding work efforts directory from a subdirectory.
----------------------------------------------------------------------
Traceback (most recent call last):
  File "/Users/ctavolazzi/Code/code_conductor/tests/test_config_system.py", line 143, in test_find_work_efforts_dir_from_subdir
    self.assertEqual(work_dir, self.work_efforts_dir)
AssertionError: '/Users/ctavolazzi/Code/code_conductor/.AI-[14 chars]orts' != '/var/folders/xs/91hrztpj6hvgcqdz_fkxrcdc00[37 chars]orts'
- /Users/ctavolazzi/Code/code_conductor/_AI-Setup/work_efforts
+ /var/folders/xs/91hrztpj6hvgcqdz_fkxrcdc0000gn/T/tmpuboxoogc/_AI-Setup/work_efforts


======================================================================
FAIL: test_find_work_efforts_dir_no_config (tests.test_config_system.TestConfigSystem)
Test finding work efforts directory when no config exists.
----------------------------------------------------------------------
Traceback (most recent call last):
  File "/Users/ctavolazzi/Code/code_conductor/tests/test_config_system.py", line 128, in test_find_work_efforts_dir_no_config
    self.assertEqual(work_dir, self.work_efforts_dir)
AssertionError: '/Users/ctavolazzi/Code/code_conductor/.AI-[14 chars]orts' != '/var/folders/xs/91hrztpj6hvgcqdz_fkxrcdc00[37 chars]orts'
- /Users/ctavolazzi/Code/code_conductor/_AI-Setup/work_efforts
+ /var/folders/xs/91hrztpj6hvgcqdz_fkxrcdc0000gn/T/tmp_doi5i7u/_AI-Setup/work_efforts


======================================================================
FAIL: test_find_work_efforts_dir_with_config (tests.test_config_system.TestConfigSystem)
Test finding work efforts directory when config exists.
----------------------------------------------------------------------
Traceback (most recent call last):
  File "/Users/ctavolazzi/Code/code_conductor/tests/test_config_system.py", line 97, in test_find_work_efforts_dir_with_config
    self.assertEqual(work_dir, self.work_efforts_dir)
AssertionError: '/Users/ctavolazzi/Code/code_conductor/.AI-[14 chars]orts' != '/var/folders/xs/91hrztpj6hvgcqdz_fkxrcdc00[37 chars]orts'
- /Users/ctavolazzi/Code/code_conductor/_AI-Setup/work_efforts
+ /var/folders/xs/91hrztpj6hvgcqdz_fkxrcdc0000gn/T/tmpsnv8ebcq/_AI-Setup/work_efforts


======================================================================
FAIL: test_find_work_efforts_dir_with_root_config (tests.test_config_system.TestConfigSystem)
Test finding work efforts directory when config specifies root location.
----------------------------------------------------------------------
Traceback (most recent call last):
  File "/Users/ctavolazzi/Code/code_conductor/tests/test_config_system.py", line 116, in test_find_work_efforts_dir_with_root_config
    self.assertEqual(work_dir, root_work_efforts)
AssertionError: '/Users/ctavolazzi/Code/code_conductor/_AI-Setup/work_efforts' != '/var/folders/xs/91hrztpj6hvgcqdz_fkxrcdc0000gn/T/tmp5f3dskn_/work_efforts'
- /Users/ctavolazzi/Code/code_conductor/_AI-Setup/work_efforts
+ /var/folders/xs/91hrztpj6hvgcqdz_fkxrcdc0000gn/T/tmp5f3dskn_/work_efforts


======================================================================
FAIL: test_setup_with_config (tests.test_config_system.TestConfigSystem)
Test setup creates and uses config file.
----------------------------------------------------------------------
Traceback (most recent call last):
  File "/Library/Frameworks/Python.framework/Versions/3.10/lib/python3.10/unittest/mock.py", line 1370, in patched
    return func(*newargs, **newkeywargs)
  File "/Users/ctavolazzi/Code/code_conductor/tests/test_config_system.py", line 161, in test_setup_with_config
    self.assertTrue(os.path.exists(self.config_file))
AssertionError: False is not true

----------------------------------------------------------------------
Ran 8 tests in 0.048s

FAILED (failures=5, errors=1)
