# Code Conductor Test Report
Generated on: Sun Mar  9 15:28:46 PDT 2025
Version: Code Conductor version 0.4.3
Verbose mode: disabled
Test mode: all tests

## Environment Check
✅ Python 3: Python 3.10.0

✅ Bash: GNU bash, version 3.2.57(1)-release (x86_64-apple-darwin21)

✅ code-conductor: Code Conductor version 0.4.3

✅ Tests directory exists

# CLI Tests Tests

## Test config system
**Type:** Python Test
**Command:** `python3 ./tests/test_config_system.py`
**Timeout:** 30s

**Result:** ❌ FAILED (Exit code: 1)
**Duration:** 1s
### Output Summary
```
$ python3 ./tests/test_config_system.py
----------------------------------------
2025-03-09 15:28:47,326 - CodeConductor - INFO - Wrote config to: /var/folders/xs/91hrztpj6hvgcqdz_fkxrcdc0000gn/T/tmpkr0fuj0d/.AI-Setup/config.json
E2025-03-09 15:28:47,330 - CodeConductor - INFO - Wrote config to: /var/folders/xs/91hrztpj6hvgcqdz_fkxrcdc0000gn/T/tmpsg30ln2r/.AI-Setup/config.json
2025-03-09 15:28:47,330 - CodeConductor - INFO - Found config file at: /var/folders/xs/91hrztpj6hvgcqdz_fkxrcdc0000gn/T/tmpsg30ln2r/.AI-Setup/config.json
.2025-03-09 15:28:47,333 - CodeConductor - INFO - Wrote config to: /var/folders/xs/91hrztpj6hvgcqdz_fkxrcdc0000gn/T/tmp4x39qexc/.AI-Setup/config.json
2025-03-09 15:28:47,334 - CodeConductor - INFO - Found config file at: /Users/ctavolazzi/Code/code_conductor/.AI-Setup/config.json
F2025-03-09 15:28:47,337 - CodeConductor - INFO - Found config file at: /Users/ctavolazzi/Code/code_conductor/.AI-Setup/config.json
F2025-03-09 15:28:47,341 - CodeConductor - INFO - Wrote config to: /var/folders/xs/91hrztpj6hvgcqdz_fkxrcdc0000gn/T/tmptwvrsqd6/.AI-Setup/config.json
2025-03-09 15:28:47,341 - CodeConductor - INFO - Found config file at: /Users/ctavolazzi/Code/code_conductor/.AI-Setup/config.json
F2025-03-09 15:28:47,343 - CodeConductor - INFO - Wrote config to: /var/folders/xs/91hrztpj6hvgcqdz_fkxrcdc0000gn/T/tmpul77w976/.AI-Setup/config.json
2025-03-09 15:28:47,344 - CodeConductor - INFO - Found config file at: /Users/ctavolazzi/Code/code_conductor/.AI-Setup/config.json
F/Users/ctavolazzi/Code/code_conductor/./tests/test_config_system.py:158: RuntimeWarning: coroutine 'setup_ai_in_current_dir' was never awaited
  setup_ai_in_current_dir()
RuntimeWarning: Enable tracemalloc to get the object allocation traceback
F2025-03-09 15:28:47,359 - CodeConductor - INFO - Wrote config to: /var/folders/xs/91hrztpj6hvgcqdz_fkxrcdc0000gn/T/tmpc8yryazm/.AI-Setup/config.json
2025-03-09 15:28:47,360 - CodeConductor - INFO - Read existing config from: /var/folders/xs/91hrztpj6hvgcqdz_fkxrcdc0000gn/T/tmpc8yryazm/.AI-Setup/config.json
2025-03-09 15:28:47,360 - CodeConductor - INFO - Wrote config to: /var/folders/xs/91hrztpj6hvgcqdz_fkxrcdc0000gn/T/tmpc8yryazm/.AI-Setup/config.json
.
======================================================================
ERROR: test_create_config (__main__.TestConfigSystem)
Test creating a new config file.
----------------------------------------------------------------------
Traceback (most recent call last):
  File "/Users/ctavolazzi/Code/code_conductor/./tests/test_config_system.py", line 53, in test_create_config
    self.assertEqual(config["work_efforts"]["location"], "in_ai_setup")
KeyError: 'work_efforts'

======================================================================
FAIL: test_find_work_efforts_dir_from_subdir (__main__.TestConfigSystem)

... [      91 lines total, showing first 30 and last 30] ...

+ /var/folders/xs/91hrztpj6hvgcqdz_fkxrcdc0000gn/T/tmptwvrsqd6/.AI-Setup/work_efforts


======================================================================
FAIL: test_find_work_efforts_dir_with_root_config (__main__.TestConfigSystem)
Test finding work efforts directory when config specifies root location.
----------------------------------------------------------------------
Traceback (most recent call last):
  File "/Users/ctavolazzi/Code/code_conductor/./tests/test_config_system.py", line 116, in test_find_work_efforts_dir_with_root_config
    self.assertEqual(work_dir, root_work_efforts)
AssertionError: '/Users/ctavolazzi/Code/code_conductor/.AI-Setup/work_efforts' != '/var/folders/xs/91hrztpj6hvgcqdz_fkxrcdc0000gn/T/tmpul77w976/work_efforts'
- /Users/ctavolazzi/Code/code_conductor/.AI-Setup/work_efforts
+ /var/folders/xs/91hrztpj6hvgcqdz_fkxrcdc0000gn/T/tmpul77w976/work_efforts


======================================================================
FAIL: test_setup_with_config (__main__.TestConfigSystem)
Test setup creates and uses config file.
----------------------------------------------------------------------
Traceback (most recent call last):
  File "/Library/Frameworks/Python.framework/Versions/3.10/lib/python3.10/unittest/mock.py", line 1370, in patched
    return func(*newargs, **newkeywargs)
  File "/Users/ctavolazzi/Code/code_conductor/./tests/test_config_system.py", line 161, in test_setup_with_config
    self.assertTrue(os.path.exists(self.config_file))
AssertionError: False is not true

----------------------------------------------------------------------
Ran 8 tests in 0.039s

FAILED (failures=5, errors=1)
```

[Full log file](test_reports/Test_config_system_2025-03-09_15-28-46.log)

## Category Summary: CLI Tests
- Total tests: 1
- Passed: 0
- Failed: 1

## Test Summary

| Tests | Passed | Failed | Manual Tests | Duration |
|-------|--------|--------|-------------|----------|
| 1 | 0 | 1 | 0 | 2s |

## Detailed Results

⚠️ **1/1 tests failed. Check the logs for details.** ⚠️

## Test Cleanup
The following test directories can be safely removed:
- `config_system_test`
- `multi_manager_test`

Run `rm -rf config_system_test multi_manager_test` to clean up.
